<?xml version="1.0" encoding="utf-8"?>
<!-- This URDF was automatically created by SolidWorks to URDF Exporter! Originally created by Stephen Brawner (brawner@gmail.com) 
     Commit Version: 1.5.1-0-g916b5db  Build Version: 1.5.7152.31018
     For more information, please see http://wiki.ros.org/sw_urdf_exporter -->
<robot
  name="testagv4">
  <link
    name="base_link">
    <inertial>
      <origin
        xyz="0.0674398893575431 -0.717774048933185 0.116657039991051"
        rpy="0 0 0" />
      <mass
        value="150.039258068259" />
      <inertia
        ixx="6.73708017039029"
        ixy="-0.00183011358127124"
        ixz="-0.0264701406515879"
        iyy="10.8799284720021"
        iyz="0.000444564741423121"
        izz="16.0798429492943" />
    </inertial>
    <visual>
      <origin
        xyz="0 0 0"
        rpy="0 0 0" />
      <geometry>
        <mesh
          filename="package://testagv4/meshes/base_link.STL" />
      </geometry>
      <material
        name="">
        <color
          rgba="1 1 1 1" />
      </material>
    </visual>
    <collision>
      <origin
        xyz="0 0 0"
        rpy="0 0 0" />
      <geometry>
        <mesh
          filename="package://testagv4/meshes/base_link.STL" />
      </geometry>
    </collision>
  </link>
  <link
    name="wheel1">
    <inertial>
      <origin
        xyz="-6.93889390390723E-18 1.38777878078145E-17 0.0255"
        rpy="0 0 0" />
      <mass
        value="1.26911232586332" />
      <inertia
        ixx="0.00278823977992172"
        ixy="1.0842021724855E-19"
        ixz="-4.48665302467112E-19"
        iyy="0.00278823977992172"
        iyz="-2.44136205234698E-19"
        izz="0.00502631936658169" />
    </inertial>
    <visual>
      <origin
        xyz="0 0 0"
        rpy="0 0 0" />
      <geometry>
        <mesh
          filename="package://testagv4/meshes/wheel1.STL" />
      </geometry>
      <material
        name="">
        <color
          rgba="0.752941176470588 0.752941176470588 0.752941176470588 1" />
      </material>
    </visual>
    <collision>
      <origin
        xyz="0 0 0"
        rpy="0 0 0" />
      <geometry>
        <mesh
          filename="package://testagv4/meshes/wheel1.STL" />
      </geometry>
    </collision>
  </link>
  <joint
    name="wheel1joint"
    type="continuous">
    <origin
      xyz="0.0659303117416537 -0.0689999123528446 -0.356812572991142"
      rpy="3.14159265358979 0 0.391796412189506" />
    <parent
      link="base_link" />
    <child
      link="wheel1" />
    <axis
      xyz="0 0 1" />
  </joint>
  <link
    name="wheel2">
    <inertial>
      <origin
        xyz="-1.38777878078145E-17 0 -0.0255000000000003"
        rpy="0 0 0" />
      <mass
        value="1.26911232586332" />
      <inertia
        ixx="0.00278823977992172"
        ixy="-4.33680868994202E-19"
        ixz="7.82192058830416E-19"
        iyy="0.00278823977992172"
        iyz="-1.5616080979725E-19"
        izz="0.00502631936658168" />
    </inertial>
    <visual>
      <origin
        xyz="0 0 0"
        rpy="0 0 0" />
      <geometry>
        <mesh
          filename="package://testagv4/meshes/wheel2.STL" />
      </geometry>
      <material
        name="">
        <color
          rgba="0.752941176470588 0.752941176470588 0.752941176470588 1" />
      </material>
    </visual>
    <collision>
      <origin
        xyz="0 0 0"
        rpy="0 0 0" />
      <geometry>
        <mesh
          filename="package://testagv4/meshes/wheel2.STL" />
      </geometry>
    </collision>
  </link>
  <joint
    name="wheel2joint"
    type="continuous">
    <origin
      xyz="0.0659303117416766 -0.0689999123529007 -1.02781257314827"
      rpy="0 0 0.391796412189507" />
    <parent
      link="base_link" />
    <child
      link="wheel2" />
    <axis
      xyz="0 0 1" />
  </joint>
</robot>